<?xml version="1.0"?>
<robot xmlns:xacro="http://www.ros.org/wiki/xacro" name="broski">

  <link name="base_link">
    <visual>
      <geometry>
        <box size="0.2 0.2 0.5"/>
      </geometry>
      <material name="blue">
        <color rgba="0 0 .8 1"/>
      </material>
    </visual>
    <collision>
      <geometry>
        <box size="0.2 0.2 0.5"/>
      </geometry>
    </collision>
    <inertial>
      <mass value="10"/>
      <inertia ixx="0.083" iyy="0.083" izz="0.0133" ixy="0" ixz="0" iyz="0"/>
    </inertial>
  </link>

  <gazebo reference="base_link">
    <static>true</static>
  </gazebo>

<gazebo reference="link1">
    <static>true</static>
  </gazebo>

  <gazebo reference="link2">
    <static>true</static>
  </gazebo>


  <link name="link1">
    <visual>
      <origin xyz="0 0 0.3"/>
      <geometry>
        <box size="0.05 0.05 0.6"/>
      </geometry>
      <material name="red">
        <color rgba="0.8 0 0 1"/>
      </material>
    </visual>
    <collision>
      <origin xyz="0 0 0.3" rpy="0 0 0"/>
      <geometry>
        <box size="0.05 0.05 0.6"/>
      </geometry>
    </collision>
    <inertial>
      <mass value="10"/>
      <inertia ixx="0.625" iyy="0.625" izz="0.13" ixy="0" ixz="0" iyz="0"/>
    </inertial>
  </link>

  <link name="world"/>

  <joint name="fixed_base" type="fixed">
    <parent link="world"/>
    <child link="base_link"/>
    <origin xyz="0 0 0" rpy="0 0 0"/>
  </joint>


  <joint name="joint1" type="revolute">
      <parent link="base_link"/>
      <child link="link1"/>
      <origin xyz="0 0 0.5" rpy="0 0 0"/>
      <axis xyz="1 0 0"/>
      <limit lower="-1.57" upper="1.57" effort= "1000.00" velocity = "0.5"/>
  </joint>


  <link name="link2">
    <visual>
      <origin xyz="0 0 0.3"/>
      <geometry>
        <box size="0.05 0.05 0.6"/>
      </geometry>
      <material name="green">
        <color rgba="0 .8 0 1"/>
      </material>
    </visual>
    <collision>
      <origin xyz="0 0 0.3" rpy="0 0 0"/>
      <geometry>
        <box size="0.05 0.05 0.6"/>
      </geometry>
    </collision>
    <inertial>
      <mass value="10"/>
      <inertia ixx="0.625" iyy="0.625" izz="0.13" ixy="0" ixz="0" iyz="0"/>
    </inertial>
  </link>

  <joint name="joint2" type="revolute">
      <parent link="link1"/>
      <child link="link2"/>
      <origin xyz="0 0 0.7" rpy="0 0 0"/>
      <axis xyz="1 0 0"/>
      <limit lower="-1.57" upper="1.57" effort= "10000.00" velocity = "0.5"/>
  </joint>

 <gazebo reference="link2">
  <sensor name="imu_sensor" type="imu">
    <always_on>true</always_on>
    <update_rate>100.0</update_rate>
    <imu>
      <topic>/imu/data</topic>
      <gaussian_noise>0.0</gaussian_noise>
    </imu>
    <plugin name="imu_plugin" filename="libgazebo_ros_imu_sensor.so">
      <ros>
        <remapping>~/out:=/imu/data</remapping>
      </ros>
      <frame_name>link2</frame_name>
    </plugin>
  </sensor>
</gazebo>


</robot>